2025-07-19 13:11:19,244 - RunFixedApp - INFO - Setting up environment
2025-07-19 13:11:19,256 - RunFixedApp - INFO - Created directory: data
2025-07-19 13:11:19,256 - RunFixedApp - INFO - Created directory: data/strip_profiles
2025-07-19 13:11:19,256 - RunFixedApp - INFO - Created directory: logs
2025-07-19 13:11:19,256 - RunFixedApp - INFO - Created test_strip directory: C:\Scripts\deepbluepool3\app\services\test_strip
2025-07-19 13:11:19,271 - RunFixedApp - INFO - Copied fixed test_strip_analyzer.py to C:\Scripts\deepbluepool3\app\services\test_strip\test_strip_analyzer.py
2025-07-19 13:11:19,271 - RunFixedApp - INFO - Created __init__.py file: C:\Scripts\deepbluepool3\app\services\test_strip\__init__.py
2025-07-19 13:11:19,281 - RunFixedApp - INFO - Running fixed application
2025-07-19 13:11:19,800 - PoolApp - ERROR - Could not import required modules. Check your Python path and file structure.
2025-07-19 13:11:19,800 - PoolApp - ERROR - Error during imports: No module named 'app'
2025-07-19 13:11:19,800 - RunFixedApp - ERROR - Error running application: No module named 'app'
2025-07-19 13:11:19,812 - RunFixedApp - ERROR - Traceback (most recent call last):
  File "C:\Scripts\deepbluepool3\app\pool_app_working_fix.py", line 47, in <module>
    from services.weather.weather_service import WeatherService
ModuleNotFoundError: No module named 'services.weather.weather_service'; 'services.weather' is not a package

During handling of the above exception, another exception occurred:

Traceback (most recent call last):
  File "C:\Scripts\deepbluepool3\app\pool_app_working_fix.py", line 52, in <module>
    from database_service import DatabaseService
ModuleNotFoundError: No module named 'database_service'

During handling of the above exception, another exception occurred:

Traceback (most recent call last):
  File "C:\Scripts\deepbluepool3\app\pool_app_working_fix.py", line 60, in <module>
    from app.database_service import DatabaseService
ModuleNotFoundError: No module named 'app'

During handling of the above exception, another exception occurred:

Traceback (most recent call last):
  File "C:\Scripts\deepbluepool3\app\run_fixed_app.py", line 94, in run_application
    from pool_app_working_fix import main
  File "C:\Scripts\deepbluepool3\app\pool_app_working_fix.py", line 68, in <module>
    from app.services.database_service import DatabaseService
ModuleNotFoundError: No module named 'app'

